<?xml version="1.0" ?>
<!-- =================================================================================== -->
<!-- |    This document was autogenerated by xacro from /catkin_ws/src/maxxii/urdf/robot.xacro | -->
<!-- |    EDITING THIS FILE BY HAND IS NOT RECOMMENDED                                 | -->
<!-- =================================================================================== -->
<robot name="robot">
  <!-- Define materials EOOO -->
  <material name="green">
    <color rgba="0 1 0 1.0"/>
  </material>
  <material name="grey">
    <color rgba="0.296875 0.296875 0.296875 1.0"/>
  </material>
  <material name="yellow">
    <color rgba="0.75 0.75 0 1.0"/>
  </material>
  <material name="blue">
    <color rgba="0.0390625 0.48828125 0.70703125 1.0"/>
  </material>
  <material name="black">
    <color rgba="0 0 0 1.0"/>
  </material>
  <link name="base_link"/>
  <link name="chassis">
    <inertial>
      <origin rpy="0 0 0" xyz="-0.0045758 0.077937 0.20368"/>
      <mass value="2.0333"/>
      <inertia ixx="0.040785" ixy="-0.00045334" ixz="7.2074E-05" iyy="0.077439" iyz="3.0873E-05" izz="0.045595"/>
    </inertial>
    <visual>
      <origin rpy="0 0 0" xyz="0 0 0"/>
      <geometry>
        <mesh filename="package://maxxii/meshes/chassis.STL"/>
      </geometry>
      <material name="green"/>
    </visual>
    <collision>
      <origin rpy="0 0 0" xyz="0 0 0"/>
      <geometry>
        <mesh filename="package://maxxii/meshes/chassis.STL"/>
      </geometry>
    </collision>
  </link>
  <joint name="chassis_joint" type="fixed">
    <origin rpy="0 0 0" xyz="0 0.225 0"/>
    <parent link="base_link"/>
    <child link="chassis"/>
    <axis xyz="0 0 0"/>
  </joint>
  <link name="ponte1">
    <visual>
      <origin rpy="0 0 0" xyz="0 0 0"/>
      <geometry>
        <mesh filename="package://maxxii/meshes/meshes1/ponte1.STL"/>
      </geometry>
      <material name="grey"/>
    </visual>
  </link>
  <joint name="ponte1_joint" type="fixed">
    <origin rpy="0 0 0" xyz="0 0.225 0"/>
    <parent link="base_link"/>
    <child link="ponte1"/>
    <axis xyz="0 0 0"/>
  </joint>
  <link name="cingolo1">
    <inertial>
      <origin rpy="0 0 0" xyz="-0.0186478543961228 0.0173558435086227 0"/>
      <mass value="5.37116770201882"/>
      <inertia ixx="0.119835058050815" ixy="0.0195379499468078" ixz="4.85729027387283E-17" iyy="0.414599681845954" iyz="3.20551941809325E-17" izz="0.519305950869416"/>
    </inertial>
    <visual>
      <origin rpy="0 0 0" xyz="0 0 0"/>
      <geometry>
        <mesh filename="package://maxxii/meshes/meshes1/cingolo1.STL"/>
      </geometry>
      <material name="grey"/>
    </visual>
    <collision>
      <origin rpy="0 0 0" xyz="0 0 0"/>
      <geometry>
        <mesh filename="package://maxxii/meshes/meshes1/cingolo1.STL"/>
      </geometry>
    </collision>
  </link>
  <joint name="cingolo1_joint" type="fixed">
    <origin rpy="1.5707963267949 0 3.14" xyz="-0.094340414586262 -0.301388567 -0.100112309063136"/>
    <parent link="base_link"/>
    <child link="cingolo1"/>
    <axis xyz="0 0 0"/>
  </joint>
  <link name="supporto_ruote1">
    <visual>
      <origin rpy="0 0 0" xyz="0 0 0"/>
      <geometry>
        <mesh filename="package://maxxii/meshes/meshes1/supporto_ruote1.STL"/>
      </geometry>
      <material name="green"/>
    </visual>
  </link>
  <joint name="supporto_ruote1_joint" type="fixed">
    <origin rpy="-2.45232668596043 0 1.57" xyz="-0.249653977391183 -0.353238567 -0.0779139783362333"/>
    <parent link="base_link"/>
    <child link="supporto_ruote1"/>
    <axis xyz="0 0 0"/>
  </joint>
  <link name="sospensioni1">
    <visual>
      <origin rpy="0 0 0" xyz="0 0 0"/>
      <geometry>
        <mesh filename="package://maxxii/meshes/meshes1/sospensioni1.STL"/>
      </geometry>
      <material>
        <color rgba="0.529411764705882 0.549019607843137 0.549019607843137 1"/>
      </material>
    </visual>
  </link>
  <joint name="sospensioni1_joint" type="fixed">
    <origin rpy="-1.91368272087089 0 -1.5707963267949" xyz="0.115815637360445 -0.300738567 -0.0224356268106508"/>
    <parent link="base_link"/>
    <child link="sospensioni1"/>
    <axis xyz="0 0 0"/>
  </joint>
  <link name="assi1">
    <visual>
      <origin rpy="0 0 0" xyz="0 0 0"/>
      <geometry>
        <mesh filename="package://maxxii/meshes/meshes1/assi1.STL"/>
      </geometry>
      <material name="grey"/>
    </visual>
  </link>
  <joint name="assi1_joint" type="fixed">
    <origin rpy="-1.91580745395575 0 1.57" xyz="-0.399632572527583 -0.302738567 -0.131814051628503"/>
    <parent link="base_link"/>
    <child link="assi1"/>
    <axis xyz="0 0 0"/>
  </joint>
  <link name="ruote_folli1">
    <visual>
      <origin rpy="0 0 0" xyz="0 0 0"/>
      <geometry>
        <mesh filename="package://maxxii/meshes/meshes1/ruote_folli1.STL"/>
      </geometry>
      <material name="black"/>
    </visual>
  </link>
  <joint name="ruote_folli1_joint" type="fixed">
    <origin rpy="-1.5707963267949 -1.29575751456647 3.14" xyz="-0.399632572527583 -0.302738567 -0.131814051628503"/>
    <parent link="base_link"/>
    <child link="ruote_folli1"/>
    <axis xyz="0 0 0"/>
  </joint>
  <link name="ruota_motrice1">
    <visual>
      <origin rpy="0 0 0" xyz="0 0 0"/>
      <geometry>
        <mesh filename="package://maxxii/meshes/meshes1/ruota_motrice1.STL"/>
      </geometry>
      <material name="black"/>
    </visual>
  </link>
  <joint name="ruota_motrice1_joint" type="fixed">
    <origin rpy="-1.5707963267949 -1.22950532384837 3.14" xyz="-0.096734450942382 -0.286388567 0.087326977068925"/>
    <parent link="base_link"/>
    <child link="ruota_motrice1"/>
    <axis xyz="0 0 0"/>
  </joint>
  <link name="ponte2">
    <visual>
      <origin rpy="0 0 0" xyz="0 0 0"/>
      <geometry>
        <mesh filename="package://maxxii/meshes/meshes2/ponte2.STL"/>
      </geometry>
      <material name="grey"/>
    </visual>
  </link>
  <joint name="ponte2_joint" type="fixed">
    <origin rpy="0 0 0" xyz="0.2 0.225 0"/>
    <parent link="base_link"/>
    <child link="ponte2"/>
    <axis xyz="0 0 0"/>
  </joint>
  <link name="cingolo2">
    <inertial>
      <origin rpy="0 0 0" xyz="0.107049462041298 0.0256401339723269 0"/>
      <mass value="5.37116770201882"/>
      <inertia ixx="0.119835058050815" ixy="0.0195379499468078" ixz="4.85729027387283E-17" iyy="0.414599681845954" iyz="3.20551941809325E-17" izz="0.519305950869416"/>
    </inertial>
    <visual>
      <origin rpy="0 0 0" xyz="0 0 0"/>
      <geometry>
        <mesh filename="package://maxxii/meshes/meshes2/cingolo2.STL"/>
      </geometry>
      <material name="grey"/>
    </visual>
    <collision>
      <origin rpy="0 0 0" xyz="0 0 0"/>
      <geometry>
        <mesh filename="package://maxxii/meshes/meshes2/cingolo2.STL"/>
      </geometry>
    </collision>
  </link>
  <joint name="cingolo2_joint" type="fixed">
    <origin rpy="1.5707963267949 0 0" xyz="0.103644852098874 -0.302388567 -0.100098861028134"/>
    <parent link="base_link"/>
    <child link="cingolo2"/>
    <axis xyz="0 0 0"/>
  </joint>
  <link name="supporto_ruote2">
    <visual>
      <origin rpy="0 0 0" xyz="0 0 0"/>
      <geometry>
        <mesh filename="package://maxxii/meshes/meshes2/supporto_ruote2.STL"/>
      </geometry>
      <material name="green"/>
    </visual>
  </link>
  <joint name="supporto_ruote2_joint" type="fixed">
    <origin rpy="-2.45232668596043 0 3.14" xyz="-0.0220561355060307 -0.353388567 -0.077962456588875"/>
    <parent link="base_link"/>
    <child link="supporto_ruote2"/>
    <axis xyz="0 0 0"/>
  </joint>
  <link name="sospensioni2">
    <visual>
      <origin rpy="0 0 0" xyz="0 0 0"/>
      <geometry>
        <mesh filename="package://maxxii/meshes/meshes2/sospensioni2.STL"/>
      </geometry>
      <material>
        <color rgba="0.529411764705882 0.549019607843137 0.549019607843137 1"/>
      </material>
    </visual>
  </link>
  <joint name="sospensioni2_joint" type="fixed">
    <origin rpy="-1.22790986978825 0 1.5707963267949" xyz="0.285780963678875 -0.300738567 -0.0224356268106508"/>
    <parent link="base_link"/>
    <child link="sospensioni2"/>
    <axis xyz="0 0 0"/>
  </joint>
  <link name="assi2">
    <visual>
      <origin rpy="0 0 0" xyz="0 0 0"/>
      <geometry>
        <mesh filename="package://maxxii/meshes/meshes2/assi2.STL"/>
      </geometry>
      <material name="grey"/>
    </visual>
  </link>
  <joint name="assi2_joint" type="fixed">
    <origin rpy="-1.22578519963396 0 0" xyz="0.399632572527583 -0.302738567 -0.131814051628503"/>
    <parent link="base_link"/>
    <child link="assi2"/>
    <axis xyz="0 0 0"/>
  </joint>
  <link name="ruote_folli2">
    <visual>
      <origin rpy="0 0 0" xyz="0 0 0"/>
      <geometry>
        <mesh filename="package://maxxii/meshes/meshes2/ruote_folli2.STL"/>
      </geometry>
      <material name="black"/>
    </visual>
  </link>
  <joint name="ruote_folli2_joint" type="fixed">
    <origin rpy="-1.5707963267949 -1.91580745395575 0" xyz="0.399632572527583 -0.302738567 -0.131814051628503"/>
    <parent link="base_link"/>
    <child link="ruote_folli2"/>
    <axis xyz="0 0 0"/>
  </joint>
  <link name="ruota_motrice2">
    <visual>
      <origin rpy="0 0 0" xyz="0 0 0"/>
      <geometry>
        <mesh filename="package://maxxii/meshes/meshes2/ruota_motrice2.STL"/>
      </geometry>
      <material name="black"/>
    </visual>
  </link>
  <joint name="ruota_motrice2_joint" type="fixed">
    <origin rpy="-1.5707963267949 -1.91208748794719 0" xyz="0.096734450942382 -0.286388567 0.087326977068925"/>
    <parent link="base_link"/>
    <child link="ruota_motrice2"/>
    <axis xyz="0 0 0"/>
  </joint>
  <!-- Use macros and properties -->
  <link name="front_left_wheel">
    <!-- <visual>
            <geometry>
                <cylinder radius="${radius}" length="${length}" />
            </geometry>
        </visual> -->
    <collision>
      <geometry>
        <cylinder length="0.13" radius="0.15"/>
      </geometry>
    </collision>
    <inertial>
      <origin xyz="0 0 0"/>
      <mass value="4"/>
      <!-- Inertia matrix calculation for a cylinder -->
      <inertia ixx="0.02813333333333333" ixy="0.0" ixz="0.0" iyy="0.02813333333333333" iyz="0.0" izz="0.02813333333333333"/>
    </inertial>
  </link>
  <joint name="front_left_wheel_joint" type="continuous">
    <origin rpy=" -1.57 0 0" xyz="0.15 0.305 -0.105"/>
    <parent link="base_link"/>
    <child link="front_left_wheel"/>
    <axis xyz="0 0 1"/>
  </joint>
  <transmission name="trans_front_left_wheel">
    <type>transmission_interface/SimpleTransmission</type>
    <joint name="front_left_wheel_joint">
      <hardwareInterface>hardware_interface/VelocityJointInterface</hardwareInterface>
    </joint>
    <actuator name="motor_front_left_wheel">
      <mechanicalReduction>100</mechanicalReduction>
    </actuator>
  </transmission>
  <gazebo reference="front_left_wheel">
    <gravity>true</gravity>
    <mu1>1</mu1>
    <mu2>1</mu2>
    <kd>1</kd>
    <kp>10000000000.0</kp>
    <fdir1>0 0 1</fdir1>
    <selfCollide>false</selfCollide>
  </gazebo>
  <link name="front_right_wheel">
    <!-- <visual>
            <geometry>
                <cylinder radius="${radius}" length="${length}" />
            </geometry>
        </visual> -->
    <collision>
      <geometry>
        <cylinder length="0.13" radius="0.15"/>
      </geometry>
    </collision>
    <inertial>
      <origin xyz="0 0 0"/>
      <mass value="4"/>
      <!-- Inertia matrix calculation for a cylinder -->
      <inertia ixx="0.02813333333333333" ixy="0.0" ixz="0.0" iyy="0.02813333333333333" iyz="0.0" izz="0.02813333333333333"/>
    </inertial>
  </link>
  <joint name="front_right_wheel_joint" type="continuous">
    <origin rpy=" -1.57 0 0" xyz="0.15 -0.315 -0.105"/>
    <parent link="base_link"/>
    <child link="front_right_wheel"/>
    <axis xyz="0 0 1"/>
  </joint>
  <transmission name="trans_front_right_wheel">
    <type>transmission_interface/SimpleTransmission</type>
    <joint name="front_right_wheel_joint">
      <hardwareInterface>hardware_interface/VelocityJointInterface</hardwareInterface>
    </joint>
    <actuator name="motor_front_right_wheel">
      <mechanicalReduction>100</mechanicalReduction>
    </actuator>
  </transmission>
  <gazebo reference="front_right_wheel">
    <gravity>true</gravity>
    <mu1>1</mu1>
    <mu2>1</mu2>
    <kd>1</kd>
    <kp>10000000000.0</kp>
    <fdir1>0 0 1</fdir1>
    <selfCollide>false</selfCollide>
  </gazebo>
  <link name="rear_left_wheel">
    <!-- <visual>
            <geometry>
                <cylinder radius="${radius}" length="${length}" />
            </geometry>
        </visual> -->
    <collision>
      <geometry>
        <cylinder length="0.13" radius="0.12"/>
      </geometry>
    </collision>
    <inertial>
      <origin xyz="0 0 0"/>
      <mass value="4.23900913"/>
      <!-- Inertia matrix calculation for a cylinder -->
      <inertia ixx="0.021230370726083334" ixy="0.0" ixz="0.0" iyy="0.021230370726083334" iyz="0.0" izz="0.021230370726083334"/>
    </inertial>
  </link>
  <joint name="rear_left_wheel_joint" type="continuous">
    <origin rpy=" -1.57 0 0" xyz="-0.35 0.305 -0.132"/>
    <parent link="base_link"/>
    <child link="rear_left_wheel"/>
    <axis xyz="0 0 1"/>
  </joint>
  <transmission name="trans_rear_left_wheel">
    <type>transmission_interface/SimpleTransmission</type>
    <joint name="rear_left_wheel_joint">
      <hardwareInterface>hardware_interface/VelocityJointInterface</hardwareInterface>
    </joint>
    <actuator name="motor_rear_left_wheel">
      <mechanicalReduction>100</mechanicalReduction>
    </actuator>
  </transmission>
  <gazebo reference="rear_left_wheel">
    <gravity>true</gravity>
    <mu1>1</mu1>
    <mu2>1</mu2>
    <kd>1</kd>
    <kp>10000000000.0</kp>
    <fdir1>0 0 1</fdir1>
    <selfCollide>false</selfCollide>
  </gazebo>
  <link name="rear_right_wheel">
    <!-- <visual>
            <geometry>
                <cylinder radius="${radius}" length="${length}" />
            </geometry>
        </visual> -->
    <collision>
      <geometry>
        <cylinder length="0.13" radius="0.12"/>
      </geometry>
    </collision>
    <inertial>
      <origin xyz="0 0 0"/>
      <mass value="4.23900913"/>
      <!-- Inertia matrix calculation for a cylinder -->
      <inertia ixx="0.021230370726083334" ixy="0.0" ixz="0.0" iyy="0.021230370726083334" iyz="0.0" izz="0.021230370726083334"/>
    </inertial>
  </link>
  <joint name="rear_right_wheel_joint" type="continuous">
    <origin rpy=" -1.57 0 0" xyz="-0.35 -0.315 -0.132"/>
    <parent link="base_link"/>
    <child link="rear_right_wheel"/>
    <axis xyz="0 0 1"/>
  </joint>
  <transmission name="trans_rear_right_wheel">
    <type>transmission_interface/SimpleTransmission</type>
    <joint name="rear_right_wheel_joint">
      <hardwareInterface>hardware_interface/VelocityJointInterface</hardwareInterface>
    </joint>
    <actuator name="motor_rear_right_wheel">
      <mechanicalReduction>100</mechanicalReduction>
    </actuator>
  </transmission>
  <gazebo reference="rear_right_wheel">
    <gravity>true</gravity>
    <mu1>1</mu1>
    <mu2>1</mu2>
    <kd>1</kd>
    <kp>10000000000.0</kp>
    <fdir1>0 0 1</fdir1>
    <selfCollide>false</selfCollide>
  </gazebo>
  <gazebo reference="gps_link">
    <material>Gazebo/Blue</material>
  </gazebo>
  <link name="gps_link">
    <visual>
      <geometry>
        <box size="0.05 0.05 0.025"/>
      </geometry>
      <origin rpy="0 0 0" xyz="0 0 0"/>
      <material name="blue">
        <color rgba="0 0 1.0 1.0"/>
      </material>
    </visual>
    <collision>
      <geometry>
        <box size="0.05 0.05 0.025"/>
      </geometry>
      <origin rpy="0 0 0" xyz="0 0 0"/>
    </collision>
    <inertial>
      <origin xyz="0 0 0"/>
      <mass value="0.01"/>
      <inertia ixx="1.0" ixy="0.0" ixz="0.0" iyy="1.0" iyz="0.0" izz="1.0"/>
    </inertial>
  </link>
  <joint name="gps_joint" type="fixed">
    <parent link="base_link"/>
    <child link="gps_link"/>
    <origin rpy="0 0 0" xyz="0.05 0 0.1875"/>
    <!--        <origin rpy="0 0 0" xyz="1.05 0 3"/>-->
  </joint>
  <gazebo>
    <plugin filename="libhector_gazebo_ros_gps.so" name="gps_controller">
      <updateRate>40</updateRate>
      <robotNamespace>/</robotNamespace>
      <bodyName>gps_link</bodyName>
      <topicName>robot/fix</topicName>
      <velocityTopicName>robot/vel</velocityTopicName>
      <referenceLatitude>40.0599536</referenceLatitude>
      <referenceLongitude>18.3458069</referenceLongitude>
      <referenceHeading>0</referenceHeading>
      <referenceAltitude>0</referenceAltitude>
      <drift>0.0001 0.0001 0.0001</drift>
      <status>1</status>
      <service>1</service>
    </plugin>
  </gazebo>
  <gazebo reference="mag_link">
    <material>Gazebo/Purple</material>
  </gazebo>
  <link name="mag_link">
    <visual>
      <geometry>
        <box size="0.1 0.1 0.1"/>
      </geometry>
      <origin rpy="0 0 0" xyz="0 0 0"/>
      <material name="purple">
        <color rgba="0.611 0.317 0.73 1"/>
      </material>
    </visual>
    <collision>
      <geometry>
        <box size="0.1 0.1 0.1"/>
      </geometry>
      <origin rpy="0 0 0" xyz="0 0 0"/>
    </collision>
    <inertial>
      <origin xyz="0 0 0"/>
      <mass value="0.01"/>
      <inertia ixx="1.0" ixy="0.0" ixz="0.0" iyy="1.0" iyz="0.0" izz="1.0"/>
    </inertial>
  </link>
  <joint name="mag_joint" type="fixed">
    <parent link="base_link"/>
    <child link="mag_link"/>
    <origin rpy="0 0 0" xyz="0 0.0 0.1"/>
  </joint>
  <gazebo>
    <plugin filename="libhector_gazebo_ros_magnetic.so" name="magnetometer">
      <updateRate>40.0</updateRate>
      <bodyname>mag_link</bodyname>
      <topicName>robot/mag</topicName>
      <referenceHeading>0</referenceHeading>
      <!-- declinazione è l'angolo tra polo nord geofrafico e polo nord magnetico -->
      <declination>0.0</declination>
      <!--polo nord geografico e polo nord magnetico sono allineati -->
      <inclination>60.0</inclination>
      <offset>0 0 0</offset>
      <driftFrequency>0 0 0</driftFrequency>
      <gaussianNoise>0 0 0</gaussianNoise>
    </plugin>
  </gazebo>
  <!-- Uncomment the line below if you have the laser.xacro -->
  <!-- <xacro:robot_laser x="0.0" y="0.0" z="0.245" laser_size="0.1"/> -->
  <!--
        The gazebo plugin aligns the depth data with the Z axis, with X=left and Y=up
        ROS expects the depth data along the X axis, with Y=left and Z=up
        This link only exists to give the gazebo plugin the correctly-oriented frame
      -->
  <gazebo reference="realsense">
    <material>Gazebo/White</material>
  </gazebo>
  <link name="realsense">
    <visual>
      <!--
            the model's origin is in the middle & it's rotated to lie in
            the optical standard with X left, Y up, and Z forward
            -->
      <origin rpy="1.570796 0 1.570796" xyz="0.0115 0 0.0100"/>
      <geometry>
        <!-- Origin of this mesh is the base of the bracket. -->
        <mesh filename="package://realsense2_description/meshes/d435.dae"/>
      </geometry>
      <material name="white">
        <color rgba="1 1 1.0 1.0"/>
      </material>
    </visual>
    <collision>
      <geometry>
        <!-- Origin of this mesh is the base of the bracket. -->
        <mesh filename="package://realsense2_description/meshes/d435.dae"/>
      </geometry>
      <origin rpy="1.570796 0 1.570796" xyz="0.0115 0 0.0100"/>
    </collision>
  </link>
  <joint name="realsense_joint" type="fixed">
    <parent link="base_link"/>
    <child link="realsense"/>
    <origin rpy="0 0 1.57" xyz="0.1 0.0 0.5"/>
  </joint>
  <gazebo reference="realsense">
    <turnGravityOff>true</turnGravityOff>
    <sensor name="realsense_depth" type="depth">
      <update_rate>30</update_rate>
      <camera>
        <!-- 75x65 degree FOV for the depth sensor -->
        <horizontal_fov>1.5184351666666667</horizontal_fov>
        <vertical_fov>1.0122901111111111</vertical_fov>
        <image>
          <width>640</width>
          <height>480</height>
          <!-- TODO: check what format the Realsense hardware delivers and set this to match! -->
          <format>RGB_INT8</format>
        </image>
        <clip>
          <!-- give the color sensor a maximum range of 50m so that the simulation renders nicely -->
          <near>0.01</near>
          <far>50.0</far>
        </clip>
      </camera>
      <plugin filename="libgazebo_ros_openni_kinect.so" name="kinect_controller">
        <baseline>0.2</baseline>
        <alwaysOn>true</alwaysOn>
        <updateRate>30</updateRate>
        <cameraName>robot/camera</cameraName>
        <imageTopicName>color/image_raw</imageTopicName>
        <cameraInfoTopicName>color/camera_info</cameraInfoTopicName>
        <depthImageTopicName>depth/image_rect_raw</depthImageTopicName>
        <depthImageInfoTopicName>depth/camera_info</depthImageInfoTopicName>
        <pointCloudTopicName>depth/color/points</pointCloudTopicName>
        <frameName>realsense</frameName>
        <pointCloudCutoff>0.105</pointCloudCutoff>
        <pointCloudCutoffMax>8.0</pointCloudCutoffMax>
        <distortionK1>0.00000001</distortionK1>
        <distortionK2>0.00000001</distortionK2>
        <distortionK3>0.00000001</distortionK3>
        <distortionT1>0.00000001</distortionT1>
        <distortionT2>0.00000001</distortionT2>
        <CxPrime>0</CxPrime>
        <Cx>0</Cx>
        <Cy>0</Cy>
        <focalLength>0</focalLength>
        <hackBaseline>0</hackBaseline>
      </plugin>
    </sensor>
  </gazebo>
  <link name="velodyne_vlp16_base_link">
    <inertial>
      <mass value="0.83"/>
      <origin xyz="0 0 0.03585"/>
      <inertia ixx="0.000908059425" ixy="0" ixz="0" iyy="0.000908059425" iyz="0" izz="0.0011049624"/>
    </inertial>
    <visual>
      <geometry>
        <mesh filename="package://velodyne_description/meshes/VLP16_base_1.dae"/>
      </geometry>
    </visual>
    <visual>
      <geometry>
        <mesh filename="package://velodyne_description/meshes/VLP16_base_2.dae"/>
      </geometry>
    </visual>
    <collision>
      <origin rpy="0 0 0" xyz="0 0 0.03585"/>
      <geometry>
        <cylinder length="0.0717" radius="0.0516"/>
      </geometry>
    </collision>
  </link>
  <joint name="velodyne_vlp16_base_joint" type="fixed">
    <origin rpy="0 0 0" xyz="-0.03 0 0.2"/>
    <parent link="base_link"/>
    <child link="velodyne_vlp16_base_link"/>
  </joint>
  <link name="velodyne_vlp16">
    <inertial>
      <mass value="0.01"/>
      <origin xyz="0 0 0"/>
      <inertia ixx="1e-7" ixy="0" ixz="0" iyy="1e-7" iyz="0" izz="1e-7"/>
    </inertial>
    <visual>
      <origin xyz="0 0 -0.0377"/>
      <geometry>
        <mesh filename="package://velodyne_description/meshes/VLP16_scan.dae"/>
      </geometry>
    </visual>
  </link>
  <joint name="velodyne_vlp16_joint" type="fixed">
    <origin rpy="0 0 0" xyz="0 0 0.0377"/>
    <parent link="velodyne_vlp16_base_link"/>
    <child link="velodyne_vlp16"/>
  </joint>
  <gazebo reference="velodyne_vlp16">
    <sensor name="VLP16" type="gpu_ray">
      <pose>0 0 0 0 0 0</pose>
      <visualize>false</visualize>
      <update_rate>10</update_rate>
      <ray>
        <scan>
          <horizontal>
            <samples>360</samples>
            <resolution>1</resolution>
            <min_angle>-3.141592653589793</min_angle>
            <max_angle>3.141592653589793</max_angle>
          </horizontal>
          <vertical>
            <samples>16</samples>
            <resolution>1</resolution>
            <min_angle>-0.2617993877991494</min_angle>
            <max_angle> 0.2617993877991494</max_angle>
          </vertical>
        </scan>
        <range>
          <min>1</min>
          <max>140</max>
          <resolution>0.001</resolution>
        </range>
        <noise>
          <type>gaussian</type>
          <mean>0.0</mean>
          <stddev>0.0</stddev>
        </noise>
      </ray>
      <plugin filename="libgazebo_ros_velodyne_gpu_laser.so" name="gazebo_ros_laser_controller">
        <topicName>robot/velodyne</topicName>
        <frameName>velodyne_vlp16</frameName>
        <min_range>1</min_range>
        <max_range>140</max_range>
        <gaussianNoise>0.008</gaussianNoise>
      </plugin>
    </sensor>
  </gazebo>
  <!-- Gazebo plugin -->
  <gazebo>
    <plugin filename="libgazebo_ros_control.so" name="gazebo_ros_control">
      <robotNamespace>/</robotNamespace>
    </plugin>
  </gazebo>
</robot>
