<?xml version="1.0"?>
<robot xmlns:xacro="http://www.ros.org/wiki/xacro" name="front_wheel">

<xacro:include filename="$(find wetexplorer_description)/urdf/cylinder_inertia.xacro"/>

<xacro:macro name="front_wheel" params="left_right radius length position mu">

        
    <xacro:property name="mass" value="0.15" />

    <link name="front_${left_right}_wheel">
        <!-- <visual>
            <geometry>
                <cylinder radius="${radius}" length="${length}" />
            </geometry>
        </visual> -->
        <collision>
            <geometry>
                <cylinder radius="${radius}" length="${length}" />
            </geometry>
        </collision>
        
        <xacro:cylinder_inertia mass="${mass}" radius="${radius}" length="${length}"/>
    </link>

    <joint name="front_${left_right}_wheel_joint" type="continuous">
        <origin xyz="0.18601 ${position} -0.1259" rpy=" -1.570796 0 0" />
        <parent link="base_link" />
        <child link="front_${left_right}_wheel" />
        <axis  xyz="0 0 1" />
  
    </joint>

    <transmission name="trans_front_${left_right}_wheel">
        <type>transmission_interface/SimpleTransmission</type>
        <joint name="front_${left_right}_wheel_joint">
        <hardwareInterface>hardware_interface/EffortJointInterface</hardwareInterface>
        </joint>
        <actuator name="motor_front_${left_right}_wheel">
        <mechanicalReduction>1</mechanicalReduction>
        </actuator>
    </transmission>

    <gazebo reference="front_${left_right}_wheel">
        <gravity>true</gravity>
        <mu1>${mu}</mu1>
        <mu2>${mu}</mu2>
        <kd>0.1</kd>
        <kp>1000.0</kp>
        <fdir1>0 0 1</fdir1>
        <selfCollide>false</selfCollide>
    </gazebo>

</xacro:macro>

</robot>
